Workbook

Sheet Intake Responses
A1: Opportunity ID | B1: Submitted Date | C1: Submitted By | D1: Team / Function | E1: Workflow / Task Name | F1: Workflow Owner | G1: People Involved | H1: Who Uses the Output? | I1: Purpose of the Workflow | J1: Decision / Deliverable / Outcome Supported | K1: What Happens If This Is Late Wrong or Skipped? | L1: Current Process Summary | M1: Frequency | N1: Minutes Per Run | O1: People Doing This Work | P1: Outputs / Items Per Cycle | Q1: Systems / Tools Involved | R1: Number of Systems | S1: Friction Types | T1: Pain Rating 1-5 | U1: Business Criticality 1-5 | V1: Error-Proneness 1-5 | W1: Urgency 1-5 | X1: People Affected | Y1: Customers / Districts / Students Affected | Z1: Desired Future State | AA1: What Should Still Require Human Review? | AB1: What Should Never Be Automated? | AC1: What Would Make You Trust the Improved Workflow? | AD1: What Would Make This Unusable? | AE1: How Would We Know This Worked? | AF1: Sensitive Data? | AG1: Data Types Involved | AH1: Input Data Location | AI1: Output Destination | AJ1: Existing Reports / Exports / Templates? | AK1: Example Link | AL1: Available for Live Walkthrough? | AM1: Prototype Willingness | AN1: Ideal Timeline | AO1: Initial Notes
A2: ="WF-"&TEXT(ROW()-1,"0000")
A3: ="WF-"&TEXT(ROW()-1,"0000")
A4: ="WF-"&TEXT(ROW()-1,"0000")
A5: ="WF-"&TEXT(ROW()-1,"0000")
A6: ="WF-"&TEXT(ROW()-1,"0000")
A7: ="WF-"&TEXT(ROW()-1,"0000")
A8: ="WF-"&TEXT(ROW()-1,"0000")
A9: ="WF-"&TEXT(ROW()-1,"0000")
A10: ="WF-"&TEXT(ROW()-1,"0000")
A11: ="WF-"&TEXT(ROW()-1,"0000")
A12: ="WF-"&TEXT(ROW()-1,"0000")
A13: ="WF-"&TEXT(ROW()-1,"0000")
... A501: ="WF-"&TEXT(ROW()-1,"0000")

Sheet Opportunity Scoring
A1: Opportunity ID | B1: Workflow / Task Name | C1: Team / Function | D1: Workflow Owner | E1: Status | F1: Frequency | G1: Minutes Per Run | H1: People Doing This Work | I1: Estimated Runs Per Month | J1: Estimated Monthly Hours | K1: Annualized Hours | L1: Pain Rating | M1: Business Criticality | N1: Error-Proneness | O1: Urgency | P1: People Affected | Q1: Sensitive Data? | R1: Friction Types | S1: Likely Solution Type | T1: Feasibility | U1: Risk Level | V1: Impact Score | W1: Frequency Score | X1: Friction Score | Y1: Risk Penalty | Z1: Priority Score | AA1: Priority Category | AB1: Recommended Next Step | AC1: Assignee | AD1: Next Review Date | AE1: Notes
B2: =IFERROR(XLOOKUP(A2,'Intake Responses'!$A:$A,'Intake Responses'!$E:$E),"") | C2: =IFERROR(XLOOKUP(A2,'Intake Responses'!$A:$A,'Intake Responses'!$D:$D),"") | D2: =IFERROR(XLOOKUP(A2,'Intake Responses'!$A:$A,'Intake Responses'!$F:$F),"") | F2: =IFERROR(XLOOKUP(A2,'Intake Responses'!$A:$A,'Intake Responses'!$M:$M),"") | G2: =IFERROR(XLOOKUP(A2,'Intake Responses'!$A:$A,'Intake Responses'!$N:$N),"") | H2: =IFERROR(XLOOKUP(A2,'Intake Responses'!$A:$A,'Intake Responses'!$O:$O),"") | I2: =IFERROR(SWITCH(F2,"Multiple times per day",60,"Daily",20,"Weekly",4,"Monthly",1,"Quarterly",0.33,"Ad hoc",0.5,"Unknown",0),0) | J2: =IFERROR((G2*H2*I2)/60,0) | K2: =IFERROR(J2*12,0) | L2: =IFERROR(XLOOKUP(A2,'Intake Responses'!$A:$A,'Intake Responses'!$T:$T),"") | M2: =IFERROR(XLOOKUP(A2,'Intake Responses'!$A:$A,'Intake Responses'!$U:$U),"") | N2: =IFERROR(XLOOKUP(A2,'Intake Responses'!$A:$A,'Intake Responses'!$V:$V),"") | O2: =IFERROR(XLOOKUP(A2,'Intake Responses'!$A:$A,'Intake Responses'!$W:$W),"") | P2: =IFERROR(XLOOKUP(A2,'Intake Responses'!$A:$A,'Intake Responses'!$X:$X),"") | Q2: =IFERROR(XLOOKUP(A2,'Intake Responses'!$A:$A,'Intake Responses'!$AF:$AF),"") | R2: =IFERROR(XLOOKUP(A2,'Intake Responses'!$A:$A,'Intake Responses'!$S:$S),"") | V2: =IFERROR(MIN(5,ROUND(((M2+O2)/2)+(IF(J2>=20,2,IF(J2>=10,1.5,IF(J2>=5,1,IF(J2>=1,0.5,0))))),1)),0) | W2: =IFERROR(SWITCH(F2,"Multiple times per day",5,"Daily",4,"Weekly",3,"Monthly",2,"Quarterly",1,"Ad hoc",1,"Unknown",0),0) | X2: =IFERROR(ROUND(AVERAGE(L2,N2),1),0) | Y2: =IFERROR(SWITCH(U2,"High",3,"Medium",2,"Low",0,"Unknown",1,1)+IF(Q2="Yes",2,IF(Q2="Unsure",1,0)),0) | Z2: =IFERROR(ROUND((V2*2)+(W2*1)+(X2*2)+(IF(T2="Easy",2,IF(T2="Medium",1,IF(T2="Hard",-1,0))))-(Y2*2),1),0) | AA2: =IFERROR(IF(S2="Not a fit","Not a Fit",IF(Y2>=5,"High Risk / Needs Review",IF(AND(Z2>=18,T2="Easy"),"Quick Win",IF(AND(Z2>=18,T2<>"Easy"),"Strategic Project",IF(Z2>=10,"Discovery Needed","Process Issue"))))),"") | AB2: =IFERROR(SWITCH(AA2,"Quick Win","Schedule prototype scoping conversation","Discovery Needed","Schedule workflow walkthrough","Strategic Project","Identify stakeholders and dependencies","High Risk / Needs Review","Review with Security/Legal/Data owner before solutioning","Process Issue","Explore process/template/documentation improvement","Not a Fit","Do not pursue at this time","Review manually"),"")
B3: =IFERROR(XLOOKUP(A3,'Intake Responses'!$A:$A,'Intake Responses'!$E:$E),"") | C3: =IFERROR(XLOOKUP(A3,'Intake Responses'!$A:$A,'Intake Responses'!$D:$D),"") | D3: =IFERROR(XLOOKUP(A3,'Intake Responses'!$A:$A,'Intake Responses'!$F:$F),"") | F3: =IFERROR(XLOOKUP(A3,'Intake Responses'!$A:$A,'Intake Responses'!$M:$M),"") | G3: =IFERROR(XLOOKUP(A3,'Intake Responses'!$A:$A,'Intake Responses'!$N:$N),"") | H3: =IFERROR(XLOOKUP(A3,'Intake Responses'!$A:$A,'Intake Responses'!$O:$O),"") | I3: =IFERROR(SWITCH(F3,"Multiple times per day",60,"Daily",20,"Weekly",4,"Monthly",1,"Quarterly",0.33,"Ad hoc",0.5,"Unknown",0),0) | J3: =IFERROR((G3*H3*I3)/60,0) | K3: =IFERROR(J3*12,0) | L3: =IFERROR(XLOOKUP(A3,'Intake Responses'!$A:$A,'Intake Responses'!$T:$T),"") | M3: =IFERROR(XLOOKUP(A3,'Intake Responses'!$A:$A,'Intake Responses'!$U:$U),"") | N3: =IFERROR(XLOOKUP(A3,'Intake Responses'!$A:$A,'Intake Responses'!$V:$V),"") | O3: =IFERROR(XLOOKUP(A3,'Intake Responses'!$A:$A,'Intake Responses'!$W:$W),"") | P3: =IFERROR(XLOOKUP(A3,'Intake Responses'!$A:$A,'Intake Responses'!$X:$X),"") | Q3: =IFERROR(XLOOKUP(A3,'Intake Responses'!$A:$A,'Intake Responses'!$AF:$AF),"") | R3: =IFERROR(XLOOKUP(A3,'Intake Responses'!$A:$A,'Intake Responses'!$S:$S),"") | V3: =IFERROR(MIN(5,ROUND(((M3+O3)/2)+(IF(J3>=20,2,IF(J3>=10,1.5,IF(J3>=5,1,IF(J3>=1,0.5,0))))),1)),0) | W3: =IFERROR(SWITCH(F3,"Multiple times per day",5,"Daily",4,"Weekly",3,"Monthly",2,"Quarterly",1,"Ad hoc",1,"Unknown",0),0) | X3: =IFERROR(ROUND(AVERAGE(L3,N3),1),0) | Y3: =IFERROR(SWITCH(U3,"High",3,"Medium",2,"Low",0,"Unknown",1,1)+IF(Q3="Yes",2,IF(Q3="Unsure",1,0)),0) | Z3: =IFERROR(ROUND((V3*2)+(W3*1)+(X3*2)+(IF(T3="Easy",2,IF(T3="Medium",1,IF(T3="Hard",-1,0))))-(Y3*2),1),0) | AA3: =IFERROR(IF(S3="Not a fit","Not a Fit",IF(Y3>=5,"High Risk / Needs Review",IF(AND(Z3>=18,T3="Easy"),"Quick Win",IF(AND(Z3>=18,T3<>"Easy"),"Strategic Project",IF(Z3>=10,"Discovery Needed","Process Issue"))))),"") | AB3: =IFERROR(SWITCH(AA3,"Quick Win","Schedule prototype scoping conversation","Discovery Needed","Schedule workflow walkthrough","Strategic Project","Identify stakeholders and dependencies","High Risk / Needs Review","Review with Security/Legal/Data owner before solutioning","Process Issue","Explore process/template/documentation improvement","Not a Fit","Do not pursue at this time","Review manually"),"")
B4: =IFERROR(XLOOKUP(A4,'Intake Responses'!$A:$A,'Intake Responses'!$E:$E),"") | C4: =IFERROR(XLOOKUP(A4,'Intake Responses'!$A:$A,'Intake Responses'!$D:$D),"") | D4: =IFERROR(XLOOKUP(A4,'Intake Responses'!$A:$A,'Intake Responses'!$F:$F),"") | F4: =IFERROR(XLOOKUP(A4,'Intake Responses'!$A:$A,'Intake Responses'!$M:$M),"") | G4: =IFERROR(XLOOKUP(A4,'Intake Responses'!$A:$A,'Intake Responses'!$N:$N),"") | H4: =IFERROR(XLOOKUP(A4,'Intake Responses'!$A:$A,'Intake Responses'!$O:$O),"") | I4: =IFERROR(SWITCH(F4,"Multiple times per day",60,"Daily",20,"Weekly",4,"Monthly",1,"Quarterly",0.33,"Ad hoc",0.5,"Unknown",0),0) | J4: =IFERROR((G4*H4*I4)/60,0) | K4: =IFERROR(J4*12,0) | L4: =IFERROR(XLOOKUP(A4,'Intake Responses'!$A:$A,'Intake Responses'!$T:$T),"") | M4: =IFERROR(XLOOKUP(A4,'Intake Responses'!$A:$A,'Intake Responses'!$U:$U),"") | N4: =IFERROR(XLOOKUP(A4,'Intake Responses'!$A:$A,'Intake Responses'!$V:$V),"") | O4: =IFERROR(XLOOKUP(A4,'Intake Responses'!$A:$A,'Intake Responses'!$W:$W),"") | P4: =IFERROR(XLOOKUP(A4,'Intake Responses'!$A:$A,'Intake Responses'!$X:$X),"") | Q4: =IFERROR(XLOOKUP(A4,'Intake Responses'!$A:$A,'Intake Responses'!$AF:$AF),"") | R4: =IFERROR(XLOOKUP(A4,'Intake Responses'!$A:$A,'Intake Responses'!$S:$S),"") | V4: =IFERROR(MIN(5,ROUND(((M4+O4)/2)+(IF(J4>=20,2,IF(J4>=10,1.5,IF(J4>=5,1,IF(J4>=1,0.5,0))))),1)),0) | W4: =IFERROR(SWITCH(F4,"Multiple times per day",5,"Daily",4,"Weekly",3,"Monthly",2,"Quarterly",1,"Ad hoc",1,"Unknown",0),0) | X4: =IFERROR(ROUND(AVERAGE(L4,N4),1),0) | Y4: =IFERROR(SWITCH(U4,"High",3,"Medium",2,"Low",0,"Unknown",1,1)+IF(Q4="Yes",2,IF(Q4="Unsure",1,0)),0) | Z4: =IFERROR(ROUND((V4*2)+(W4*1)+(X4*2)+(IF(T4="Easy",2,IF(T4="Medium",1,IF(T4="Hard",-1,0))))-(Y4*2),1),0) | AA4: =IFERROR(IF(S4="Not a fit","Not a Fit",IF(Y4>=5,"High Risk / Needs Review",IF(AND(Z4>=18,T4="Easy"),"Quick Win",IF(AND(Z4>=18,T4<>"Easy"),"Strategic Project",IF(Z4>=10,"Discovery Needed","Process Issue"))))),"") | AB4: =IFERROR(SWITCH(AA4,"Quick Win","Schedule prototype scoping conversation","Discovery Needed","Schedule workflow walkthrough","Strategic Project","Identify stakeholders and dependencies","High Risk / Needs Review","Review with Security/Legal/Data owner before solutioning","Process Issue","Explore process/template/documentation improvement","Not a Fit","Do not pursue at this time","Review manually"),"")
B5: =IFERROR(XLOOKUP(A5,'Intake Responses'!$A:$A,'Intake Responses'!$E:$E),"") | C5: =IFERROR(XLOOKUP(A5,'Intake Responses'!$A:$A,'Intake Responses'!$D:$D),"") | D5: =IFERROR(XLOOKUP(A5,'Intake Responses'!$A:$A,'Intake Responses'!$F:$F),"") | F5: =IFERROR(XLOOKUP(A5,'Intake Responses'!$A:$A,'Intake Responses'!$M:$M),"") | G5: =IFERROR(XLOOKUP(A5,'Intake Responses'!$A:$A,'Intake Responses'!$N:$N),"") | H5: =IFERROR(XLOOKUP(A5,'Intake Responses'!$A:$A,'Intake Responses'!$O:$O),"") | I5: =IFERROR(SWITCH(F5,"Multiple times per day",60,"Daily",20,"Weekly",4,"Monthly",1,"Quarterly",0.33,"Ad hoc",0.5,"Unknown",0),0) | J5: =IFERROR((G5*H5*I5)/60,0) | K5: =IFERROR(J5*12,0) | L5: =IFERROR(XLOOKUP(A5,'Intake Responses'!$A:$A,'Intake Responses'!$T:$T),"") | M5: =IFERROR(XLOOKUP(A5,'Intake Responses'!$A:$A,'Intake Responses'!$U:$U),"") | N5: =IFERROR(XLOOKUP(A5,'Intake Responses'!$A:$A,'Intake Responses'!$V:$V),"") | O5: =IFERROR(XLOOKUP(A5,'Intake Responses'!$A:$A,'Intake Responses'!$W:$W),"") | P5: =IFERROR(XLOOKUP(A5,'Intake Responses'!$A:$A,'Intake Responses'!$X:$X),"") | Q5: =IFERROR(XLOOKUP(A5,'Intake Responses'!$A:$A,'Intake Responses'!$AF:$AF),"") | R5: =IFERROR(XLOOKUP(A5,'Intake Responses'!$A:$A,'Intake Responses'!$S:$S),"") | V5: =IFERROR(MIN(5,ROUND(((M5+O5)/2)+(IF(J5>=20,2,IF(J5>=10,1.5,IF(J5>=5,1,IF(J5>=1,0.5,0))))),1)),0) | W5: =IFERROR(SWITCH(F5,"Multiple times per day",5,"Daily",4,"Weekly",3,"Monthly",2,"Quarterly",1,"Ad hoc",1,"Unknown",0),0) | X5: =IFERROR(ROUND(AVERAGE(L5,N5),1),0) | Y5: =IFERROR(SWITCH(U5,"High",3,"Medium",2,"Low",0,"Unknown",1,1)+IF(Q5="Yes",2,IF(Q5="Unsure",1,0)),0) | Z5: =IFERROR(ROUND((V5*2)+(W5*1)+(X5*2)+(IF(T5="Easy",2,IF(T5="Medium",1,IF(T5="Hard",-1,0))))-(Y5*2),1),0) | AA5: =IFERROR(IF(S5="Not a fit","Not a Fit",IF(Y5>=5,"High Risk / Needs Review",IF(AND(Z5>=18,T5="Easy"),"Quick Win",IF(AND(Z5>=18,T5<>"Easy"),"Strategic Project",IF(Z5>=10,"Discovery Needed","Process Issue"))))),"") | AB5: =IFERROR(SWITCH(AA5,"Quick Win","Schedule prototype scoping conversation","Discovery Needed","Schedule workflow walkthrough","Strategic Project","Identify stakeholders and dependencies","High Risk / Needs Review","Review with Security/Legal/Data owner before solutioning","Process Issue","Explore process/template/documentation improvement","Not a Fit","Do not pursue at this time","Review manually"),"")
B6: =IFERROR(XLOOKUP(A6,'Intake Responses'!$A:$A,'Intake Responses'!$E:$E),"") | C6: =IFERROR(XLOOKUP(A6,'Intake Responses'!$A:$A,'Intake Responses'!$D:$D),"") | D6: =IFERROR(XLOOKUP(A6,'Intake Responses'!$A:$A,'Intake Responses'!$F:$F),"") | F6: =IFERROR(XLOOKUP(A6,'Intake Responses'!$A:$A,'Intake Responses'!$M:$M),"") | G6: =IFERROR(XLOOKUP(A6,'Intake Responses'!$A:$A,'Intake Responses'!$N:$N),"") | H6: =IFERROR(XLOOKUP(A6,'Intake Responses'!$A:$A,'Intake Responses'!$O:$O),"") | I6: =IFERROR(SWITCH(F6,"Multiple times per day",60,"Daily",20,"Weekly",4,"Monthly",1,"Quarterly",0.33,"Ad hoc",0.5,"Unknown",0),0) | J6: =IFERROR((G6*H6*I6)/60,0) | K6: =IFERROR(J6*12,0) | L6: =IFERROR(XLOOKUP(A6,'Intake Responses'!$A:$A,'Intake Responses'!$T:$T),"") | M6: =IFERROR(XLOOKUP(A6,'Intake Responses'!$A:$A,'Intake Responses'!$U:$U),"") | N6: =IFERROR(XLOOKUP(A6,'Intake Responses'!$A:$A,'Intake Responses'!$V:$V),"") | O6: =IFERROR(XLOOKUP(A6,'Intake Responses'!$A:$A,'Intake Responses'!$W:$W),"") | P6: =IFERROR(XLOOKUP(A6,'Intake Responses'!$A:$A,'Intake Responses'!$X:$X),"") | Q6: =IFERROR(XLOOKUP(A6,'Intake Responses'!$A:$A,'Intake Responses'!$AF:$AF),"") | R6: =IFERROR(XLOOKUP(A6,'Intake Responses'!$A:$A,'Intake Responses'!$S:$S),"") | V6: =IFERROR(MIN(5,ROUND(((M6+O6)/2)+(IF(J6>=20,2,IF(J6>=10,1.5,IF(J6>=5,1,IF(J6>=1,0.5,0))))),1)),0) | W6: =IFERROR(SWITCH(F6,"Multiple times per day",5,"Daily",4,"Weekly",3,"Monthly",2,"Quarterly",1,"Ad hoc",1,"Unknown",0),0) | X6: =IFERROR(ROUND(AVERAGE(L6,N6),1),0) | Y6: =IFERROR(SWITCH(U6,"High",3,"Medium",2,"Low",0,"Unknown",1,1)+IF(Q6="Yes",2,IF(Q6="Unsure",1,0)),0) | Z6: =IFERROR(ROUND((V6*2)+(W6*1)+(X6*2)+(IF(T6="Easy",2,IF(T6="Medium",1,IF(T6="Hard",-1,0))))-(Y6*2),1),0) | AA6: =IFERROR(IF(S6="Not a fit","Not a Fit",IF(Y6>=5,"High Risk / Needs Review",IF(AND(Z6>=18,T6="Easy"),"Quick Win",IF(AND(Z6>=18,T6<>"Easy"),"Strategic Project",IF(Z6>=10,"Discovery Needed","Process Issue"))))),"") | AB6: =IFERROR(SWITCH(AA6,"Quick Win","Schedule prototype scoping conversation","Discovery Needed","Schedule workflow walkthrough","Strategic Project","Identify stakeholders and dependencies","High Risk / Needs Review","Review with Security/Legal/Data owner before solutioning","Process Issue","Explore process/template/documentation improvement","Not a Fit","Do not pursue at this time","Review manually"),"")
B7: =IFERROR(XLOOKUP(A7,'Intake Responses'!$A:$A,'Intake Responses'!$E:$E),"") | C7: =IFERROR(XLOOKUP(A7,'Intake Responses'!$A:$A,'Intake Responses'!$D:$D),"") | D7: =IFERROR(XLOOKUP(A7,'Intake Responses'!$A:$A,'Intake Responses'!$F:$F),"") | F7: =IFERROR(XLOOKUP(A7,'Intake Responses'!$A:$A,'Intake Responses'!$M:$M),"") | G7: =IFERROR(XLOOKUP(A7,'Intake Responses'!$A:$A,'Intake Responses'!$N:$N),"") | H7: =IFERROR(XLOOKUP(A7,'Intake Responses'!$A:$A,'Intake Responses'!$O:$O),"") | I7: =IFERROR(SWITCH(F7,"Multiple times per day",60,"Daily",20,"Weekly",4,"Monthly",1,"Quarterly",0.33,"Ad hoc",0.5,"Unknown",0),0) | J7: =IFERROR((G7*H7*I7)/60,0) | K7: =IFERROR(J7*12,0) | L7: =IFERROR(XLOOKUP(A7,'Intake Responses'!$A:$A,'Intake Responses'!$T:$T),"") | M7: =IFERROR(XLOOKUP(A7,'Intake Responses'!$A:$A,'Intake Responses'!$U:$U),"") | N7: =IFERROR(XLOOKUP(A7,'Intake Responses'!$A:$A,'Intake Responses'!$V:$V),"") | O7: =IFERROR(XLOOKUP(A7,'Intake Responses'!$A:$A,'Intake Responses'!$W:$W),"") | P7: =IFERROR(XLOOKUP(A7,'Intake Responses'!$A:$A,'Intake Responses'!$X:$X),"") | Q7: =IFERROR(XLOOKUP(A7,'Intake Responses'!$A:$A,'Intake Responses'!$AF:$AF),"") | R7: =IFERROR(XLOOKUP(A7,'Intake Responses'!$A:$A,'Intake Responses'!$S:$S),"") | V7: =IFERROR(MIN(5,ROUND(((M7+O7)/2)+(IF(J7>=20,2,IF(J7>=10,1.5,IF(J7>=5,1,IF(J7>=1,0.5,0))))),1)),0) | W7: =IFERROR(SWITCH(F7,"Multiple times per day",5,"Daily",4,"Weekly",3,"Monthly",2,"Quarterly",1,"Ad hoc",1,"Unknown",0),0) | X7: =IFERROR(ROUND(AVERAGE(L7,N7),1),0) | Y7: =IFERROR(SWITCH(U7,"High",3,"Medium",2,"Low",0,"Unknown",1,1)+IF(Q7="Yes",2,IF(Q7="Unsure",1,0)),0) | Z7: =IFERROR(ROUND((V7*2)+(W7*1)+(X7*2)+(IF(T7="Easy",2,IF(T7="Medium",1,IF(T7="Hard",-1,0))))-(Y7*2),1),0) | AA7: =IFERROR(IF(S7="Not a fit","Not a Fit",IF(Y7>=5,"High Risk / Needs Review",IF(AND(Z7>=18,T7="Easy"),"Quick Win",IF(AND(Z7>=18,T7<>"Easy"),"Strategic Project",IF(Z7>=10,"Discovery Needed","Process Issue"))))),"") | AB7: =IFERROR(SWITCH(AA7,"Quick Win","Schedule prototype scoping conversation","Discovery Needed","Schedule workflow walkthrough","Strategic Project","Identify stakeholders and dependencies","High Risk / Needs Review","Review with Security/Legal/Data owner before solutioning","Process Issue","Explore process/template/documentation improvement","Not a Fit","Do not pursue at this time","Review manually"),"")
B8: =IFERROR(XLOOKUP(A8,'Intake Responses'!$A:$A,'Intake Responses'!$E:$E),"") | C8: =IFERROR(XLOOKUP(A8,'Intake Responses'!$A:$A,'Intake Responses'!$D:$D),"") | D8: =IFERROR(XLOOKUP(A8,'Intake Responses'!$A:$A,'Intake Responses'!$F:$F),"") | F8: =IFERROR(XLOOKUP(A8,'Intake Responses'!$A:$A,'Intake Responses'!$M:$M),"") | G8: =IFERROR(XLOOKUP(A8,'Intake Responses'!$A:$A,'Intake Responses'!$N:$N),"") | H8: =IFERROR(XLOOKUP(A8,'Intake Responses'!$A:$A,'Intake Responses'!$O:$O),"") | I8: =IFERROR(SWITCH(F8,"Multiple times per day",60,"Daily",20,"Weekly",4,"Monthly",1,"Quarterly",0.33,"Ad hoc",0.5,"Unknown",0),0) | J8: =IFERROR((G8*H8*I8)/60,0) | K8: =IFERROR(J8*12,0) | L8: =IFERROR(XLOOKUP(A8,'Intake Responses'!$A:$A,'Intake Responses'!$T:$T),"") | M8: =IFERROR(XLOOKUP(A8,'Intake Responses'!$A:$A,'Intake Responses'!$U:$U),"") | N8: =IFERROR(XLOOKUP(A8,'Intake Responses'!$A:$A,'Intake Responses'!$V:$V),"") | O8: =IFERROR(XLOOKUP(A8,'Intake Responses'!$A:$A,'Intake Responses'!$W:$W),"") | P8: =IFERROR(XLOOKUP(A8,'Intake Responses'!$A:$A,'Intake Responses'!$X:$X),"") | Q8: =IFERROR(XLOOKUP(A8,'Intake Responses'!$A:$A,'Intake Responses'!$AF:$AF),"") | R8: =IFERROR(XLOOKUP(A8,'Intake Responses'!$A:$A,'Intake Responses'!$S:$S),"") | V8: =IFERROR(MIN(5,ROUND(((M8+O8)/2)+(IF(J8>=20,2,IF(J8>=10,1.5,IF(J8>=5,1,IF(J8>=1,0.5,0))))),1)),0) | W8: =IFERROR(SWITCH(F8,"Multiple times per day",5,"Daily",4,"Weekly",3,"Monthly",2,"Quarterly",1,"Ad hoc",1,"Unknown",0),0) | X8: =IFERROR(ROUND(AVERAGE(L8,N8),1),0) | Y8: =IFERROR(SWITCH(U8,"High",3,"Medium",2,"Low",0,"Unknown",1,1)+IF(Q8="Yes",2,IF(Q8="Unsure",1,0)),0) | Z8: =IFERROR(ROUND((V8*2)+(W8*1)+(X8*2)+(IF(T8="Easy",2,IF(T8="Medium",1,IF(T8="Hard",-1,0))))-(Y8*2),1),0) | AA8: =IFERROR(IF(S8="Not a fit","Not a Fit",IF(Y8>=5,"High Risk / Needs Review",IF(AND(Z8>=18,T8="Easy"),"Quick Win",IF(AND(Z8>=18,T8<>"Easy"),"Strategic Project",IF(Z8>=10,"Discovery Needed","Process Issue"))))),"") | AB8: =IFERROR(SWITCH(AA8,"Quick Win","Schedule prototype scoping conversation","Discovery Needed","Schedule workflow walkthrough","Strategic Project","Identify stakeholders and dependencies","High Risk / Needs Review","Review with Security/Legal/Data owner before solutioning","Process Issue","Explore process/template/documentation improvement","Not a Fit","Do not pursue at this time","Review manually"),"")
B9: =IFERROR(XLOOKUP(A9,'Intake Responses'!$A:$A,'Intake Responses'!$E:$E),"") | C9: =IFERROR(XLOOKUP(A9,'Intake Responses'!$A:$A,'Intake Responses'!$D:$D),"") | D9: =IFERROR(XLOOKUP(A9,'Intake Responses'!$A:$A,'Intake Responses'!$F:$F),"") | F9: =IFERROR(XLOOKUP(A9,'Intake Responses'!$A:$A,'Intake Responses'!$M:$M),"") | G9: =IFERROR(XLOOKUP(A9,'Intake Responses'!$A:$A,'Intake Responses'!$N:$N),"") | H9: =IFERROR(XLOOKUP(A9,'Intake Responses'!$A:$A,'Intake Responses'!$O:$O),"") | I9: =IFERROR(SWITCH(F9,"Multiple times per day",60,"Daily",20,"Weekly",4,"Monthly",1,"Quarterly",0.33,"Ad hoc",0.5,"Unknown",0),0) | J9: =IFERROR((G9*H9*I9)/60,0) | K9: =IFERROR(J9*12,0) | L9: =IFERROR(XLOOKUP(A9,'Intake Responses'!$A:$A,'Intake Responses'!$T:$T),"") | M9: =IFERROR(XLOOKUP(A9,'Intake Responses'!$A:$A,'Intake Responses'!$U:$U),"") | N9: =IFERROR(XLOOKUP(A9,'Intake Responses'!$A:$A,'Intake Responses'!$V:$V),"") | O9: =IFERROR(XLOOKUP(A9,'Intake Responses'!$A:$A,'Intake Responses'!$W:$W),"") | P9: =IFERROR(XLOOKUP(A9,'Intake Responses'!$A:$A,'Intake Responses'!$X:$X),"") | Q9: =IFERROR(XLOOKUP(A9,'Intake Responses'!$A:$A,'Intake Responses'!$AF:$AF),"") | R9: =IFERROR(XLOOKUP(A9,'Intake Responses'!$A:$A,'Intake Responses'!$S:$S),"") | V9: =IFERROR(MIN(5,ROUND(((M9+O9)/2)+(IF(J9>=20,2,IF(J9>=10,1.5,IF(J9>=5,1,IF(J9>=1,0.5,0))))),1)),0) | W9: =IFERROR(SWITCH(F9,"Multiple times per day",5,"Daily",4,"Weekly",3,"Monthly",2,"Quarterly",1,"Ad hoc",1,"Unknown",0),0) | X9: =IFERROR(ROUND(AVERAGE(L9,N9),1),0) | Y9: =IFERROR(SWITCH(U9,"High",3,"Medium",2,"Low",0,"Unknown",1,1)+IF(Q9="Yes",2,IF(Q9="Unsure",1,0)),0) | Z9: =IFERROR(ROUND((V9*2)+(W9*1)+(X9*2)+(IF(T9="Easy",2,IF(T9="Medium",1,IF(T9="Hard",-1,0))))-(Y9*2),1),0) | AA9: =IFERROR(IF(S9="Not a fit","Not a Fit",IF(Y9>=5,"High Risk / Needs Review",IF(AND(Z9>=18,T9="Easy"),"Quick Win",IF(AND(Z9>=18,T9<>"Easy"),"Strategic Project",IF(Z9>=10,"Discovery Needed","Process Issue"))))),"") | AB9: =IFERROR(SWITCH(AA9,"Quick Win","Schedule prototype scoping conversation","Discovery Needed","Schedule workflow walkthrough","Strategic Project","Identify stakeholders and dependencies","High Risk / Needs Review","Review with Security/Legal/Data owner before solutioning","Process Issue","Explore process/template/documentation improvement","Not a Fit","Do not pursue at this time","Review manually"),"")
B10: =IFERROR(XLOOKUP(A10,'Intake Responses'!$A:$A,'Intake Responses'!$E:$E),"") | C10: =IFERROR(XLOOKUP(A10,'Intake Responses'!$A:$A,'Intake Responses'!$D:$D),"") | D10: =IFERROR(XLOOKUP(A10,'Intake Responses'!$A:$A,'Intake Responses'!$F:$F),"") | F10: =IFERROR(XLOOKUP(A10,'Intake Responses'!$A:$A,'Intake Responses'!$M:$M),"") | G10: =IFERROR(XLOOKUP(A10,'Intake Responses'!$A:$A,'Intake Responses'!$N:$N),"") | H10: =IFERROR(XLOOKUP(A10,'Intake Responses'!$A:$A,'Intake Responses'!$O:$O),"") | I10: =IFERROR(SWITCH(F10,"Multiple times per day",60,"Daily",20,"Weekly",4,"Monthly",1,"Quarterly",0.33,"Ad hoc",0.5,"Unknown",0),0) | J10: =IFERROR((G10*H10*I10)/60,0) | K10: =IFERROR(J10*12,0) | L10: =IFERROR(XLOOKUP(A10,'Intake Responses'!$A:$A,'Intake Responses'!$T:$T),"") | M10: =IFERROR(XLOOKUP(A10,'Intake Responses'!$A:$A,'Intake Responses'!$U:$U),"") | N10: =IFERROR(XLOOKUP(A10,'Intake Responses'!$A:$A,'Intake Responses'!$V:$V),"") | O10: =IFERROR(XLOOKUP(A10,'Intake Responses'!$A:$A,'Intake Responses'!$W:$W),"") | P10: =IFERROR(XLOOKUP(A10,'Intake Responses'!$A:$A,'Intake Responses'!$X:$X),"") | Q10: =IFERROR(XLOOKUP(A10,'Intake Responses'!$A:$A,'Intake Responses'!$AF:$AF),"") | R10: =IFERROR(XLOOKUP(A10,'Intake Responses'!$A:$A,'Intake Responses'!$S:$S),"") | V10: =IFERROR(MIN(5,ROUND(((M10+O10)/2)+(IF(J10>=20,2,IF(J10>=10,1.5,IF(J10>=5,1,IF(J10>=1,0.5,0))))),1)),0) | W10: =IFERROR(SWITCH(F10,"Multiple times per day",5,"Daily",4,"Weekly",3,"Monthly",2,"Quarterly",1,"Ad hoc",1,"Unknown",0),0) | X10: =IFERROR(ROUND(AVERAGE(L10,N10),1),0) | Y10: =IFERROR(SWITCH(U10,"High",3,"Medium",2,"Low",0,"Unknown",1,1)+IF(Q10="Yes",2,IF(Q10="Unsure",1,0)),0) | Z10: =IFERROR(ROUND((V10*2)+(W10*1)+(X10*2)+(IF(T10="Easy",2,IF(T10="Medium",1,IF(T10="Hard",-1,0))))-(Y10*2),1),0) | AA10: =IFERROR(IF(S10="Not a fit","Not a Fit",IF(Y10>=5,"High Risk / Needs Review",IF(AND(Z10>=18,T10="Easy"),"Quick Win",IF(AND(Z10>=18,T10<>"Easy"),"Strategic Project",IF(Z10>=10,"Discovery Needed","Process Issue"))))),"") | AB10: =IFERROR(SWITCH(AA10,"Quick Win","Schedule prototype scoping conversation","Discovery Needed","Schedule workflow walkthrough","Strategic Project","Identify stakeholders and dependencies","High Risk / Needs Review","Review with Security/Legal/Data owner before solutioning","Process Issue","Explore process/template/documentation improvement","Not a Fit","Do not pursue at this time","Review manually"),"")
B11: =IFERROR(XLOOKUP(A11,'Intake Responses'!$A:$A,'Intake Responses'!$E:$E),"") | C11: =IFERROR(XLOOKUP(A11,'Intake Responses'!$A:$A,'Intake Responses'!$D:$D),"") | D11: =IFERROR(XLOOKUP(A11,'Intake Responses'!$A:$A,'Intake Responses'!$F:$F),"") | F11: =IFERROR(XLOOKUP(A11,'Intake Responses'!$A:$A,'Intake Responses'!$M:$M),"") | G11: =IFERROR(XLOOKUP(A11,'Intake Responses'!$A:$A,'Intake Responses'!$N:$N),"") | H11: =IFERROR(XLOOKUP(A11,'Intake Responses'!$A:$A,'Intake Responses'!$O:$O),"") | I11: =IFERROR(SWITCH(F11,"Multiple times per day",60,"Daily",20,"Weekly",4,"Monthly",1,"Quarterly",0.33,"Ad hoc",0.5,"Unknown",0),0) | J11: =IFERROR((G11*H11*I11)/60,0) | K11: =IFERROR(J11*12,0) | L11: =IFERROR(XLOOKUP(A11,'Intake Responses'!$A:$A,'Intake Responses'!$T:$T),"") | M11: =IFERROR(XLOOKUP(A11,'Intake Responses'!$A:$A,'Intake Responses'!$U:$U),"") | N11: =IFERROR(XLOOKUP(A11,'Intake Responses'!$A:$A,'Intake Responses'!$V:$V),"") | O11: =IFERROR(XLOOKUP(A11,'Intake Responses'!$A:$A,'Intake Responses'!$W:$W),"") | P11: =IFERROR(XLOOKUP(A11,'Intake Responses'!$A:$A,'Intake Responses'!$X:$X),"") | Q11: =IFERROR(XLOOKUP(A11,'Intake Responses'!$A:$A,'Intake Responses'!$AF:$AF),"") | R11: =IFERROR(XLOOKUP(A11,'Intake Responses'!$A:$A,'Intake Responses'!$S:$S),"") | V11: =IFERROR(MIN(5,ROUND(((M11+O11)/2)+(IF(J11>=20,2,IF(J11>=10,1.5,IF(J11>=5,1,IF(J11>=1,0.5,0))))),1)),0) | W11: =IFERROR(SWITCH(F11,"Multiple times per day",5,"Daily",4,"Weekly",3,"Monthly",2,"Quarterly",1,"Ad hoc",1,"Unknown",0),0) | X11: =IFERROR(ROUND(AVERAGE(L11,N11),1),0) | Y11: =IFERROR(SWITCH(U11,"High",3,"Medium",2,"Low",0,"Unknown",1,1)+IF(Q11="Yes",2,IF(Q11="Unsure",1,0)),0) | Z11: =IFERROR(ROUND((V11*2)+(W11*1)+(X11*2)+(IF(T11="Easy",2,IF(T11="Medium",1,IF(T11="Hard",-1,0))))-(Y11*2),1),0) | AA11: =IFERROR(IF(S11="Not a fit","Not a Fit",IF(Y11>=5,"High Risk / Needs Review",IF(AND(Z11>=18,T11="Easy"),"Quick Win",IF(AND(Z11>=18,T11<>"Easy"),"Strategic Project",IF(Z11>=10,"Discovery Needed","Process Issue"))))),"") | AB11: =IFERROR(SWITCH(AA11,"Quick Win","Schedule prototype scoping conversation","Discovery Needed","Schedule workflow walkthrough","Strategic Project","Identify stakeholders and dependencies","High Risk / Needs Review","Review with Security/Legal/Data owner before solutioning","Process Issue","Explore process/template/documentation improvement","Not a Fit","Do not pursue at this time","Review manually"),"")
B12: =IFERROR(XLOOKUP(A12,'Intake Responses'!$A:$A,'Intake Responses'!$E:$E),"") | C12: =IFERROR(XLOOKUP(A12,'Intake Responses'!$A:$A,'Intake Responses'!$D:$D),"") | D12: =IFERROR(XLOOKUP(A12,'Intake Responses'!$A:$A,'Intake Responses'!$F:$F),"") | F12: =IFERROR(XLOOKUP(A12,'Intake Responses'!$A:$A,'Intake Responses'!$M:$M),"") | G12: =IFERROR(XLOOKUP(A12,'Intake Responses'!$A:$A,'Intake Responses'!$N:$N),"") | H12: =IFERROR(XLOOKUP(A12,'Intake Responses'!$A:$A,'Intake Responses'!$O:$O),"") | I12: =IFERROR(SWITCH(F12,"Multiple times per day",60,"Daily",20,"Weekly",4,"Monthly",1,"Quarterly",0.33,"Ad hoc",0.5,"Unknown",0),0) | J12: =IFERROR((G12*H12*I12)/60,0) | K12: =IFERROR(J12*12,0) | L12: =IFERROR(XLOOKUP(A12,'Intake Responses'!$A:$A,'Intake Responses'!$T:$T),"") | M12: =IFERROR(XLOOKUP(A12,'Intake Responses'!$A:$A,'Intake Responses'!$U:$U),"") | N12: =IFERROR(XLOOKUP(A12,'Intake Responses'!$A:$A,'Intake Responses'!$V:$V),"") | O12: =IFERROR(XLOOKUP(A12,'Intake Responses'!$A:$A,'Intake Responses'!$W:$W),"") | P12: =IFERROR(XLOOKUP(A12,'Intake Responses'!$A:$A,'Intake Responses'!$X:$X),"") | Q12: =IFERROR(XLOOKUP(A12,'Intake Responses'!$A:$A,'Intake Responses'!$AF:$AF),"") | R12: =IFERROR(XLOOKUP(A12,'Intake Responses'!$A:$A,'Intake Responses'!$S:$S),"") | V12: =IFERROR(MIN(5,ROUND(((M12+O12)/2)+(IF(J12>=20,2,IF(J12>=10,1.5,IF(J12>=5,1,IF(J12>=1,0.5,0))))),1)),0) | W12: =IFERROR(SWITCH(F12,"Multiple times per day",5,"Daily",4,"Weekly",3,"Monthly",2,"Quarterly",1,"Ad hoc",1,"Unknown",0),0) | X12: =IFERROR(ROUND(AVERAGE(L12,N12),1),0) | Y12: =IFERROR(SWITCH(U12,"High",3,"Medium",2,"Low",0,"Unknown",1,1)+IF(Q12="Yes",2,IF(Q12="Unsure",1,0)),0) | Z12: =IFERROR(ROUND((V12*2)+(W12*1)+(X12*2)+(IF(T12="Easy",2,IF(T12="Medium",1,IF(T12="Hard",-1,0))))-(Y12*2),1),0) | AA12: =IFERROR(IF(S12="Not a fit","Not a Fit",IF(Y12>=5,"High Risk / Needs Review",IF(AND(Z12>=18,T12="Easy"),"Quick Win",IF(AND(Z12>=18,T12<>"Easy"),"Strategic Project",IF(Z12>=10,"Discovery Needed","Process Issue"))))),"") | AB12: =IFERROR(SWITCH(AA12,"Quick Win","Schedule prototype scoping conversation","Discovery Needed","Schedule workflow walkthrough","Strategic Project","Identify stakeholders and dependencies","High Risk / Needs Review","Review with Security/Legal/Data owner before solutioning","Process Issue","Explore process/template/documentation improvement","Not a Fit","Do not pursue at this time","Review manually"),"")
B13: =IFERROR(XLOOKUP(A13,'Intake Responses'!$A:$A,'Intake Responses'!$E:$E),"") | C13: =IFERROR(XLOOKUP(A13,'Intake Responses'!$A:$A,'Intake Responses'!$D:$D),"") | D13: =IFERROR(XLOOKUP(A13,'Intake Responses'!$A:$A,'Intake Responses'!$F:$F),"") | F13: =IFERROR(XLOOKUP(A13,'Intake Responses'!$A:$A,'Intake Responses'!$M:$M),"") | G13: =IFERROR(XLOOKUP(A13,'Intake Responses'!$A:$A,'Intake Responses'!$N:$N),"") | H13: =IFERROR(XLOOKUP(A13,'Intake Responses'!$A:$A,'Intake Responses'!$O:$O),"") | I13: =IFERROR(SWITCH(F13,"Multiple times per day",60,"Daily",20,"Weekly",4,"Monthly",1,"Quarterly",0.33,"Ad hoc",0.5,"Unknown",0),0) | J13: =IFERROR((G13*H13*I13)/60,0) | K13: =IFERROR(J13*12,0) | L13: =IFERROR(XLOOKUP(A13,'Intake Responses'!$A:$A,'Intake Responses'!$T:$T),"") | M13: =IFERROR(XLOOKUP(A13,'Intake Responses'!$A:$A,'Intake Responses'!$U:$U),"") | N13: =IFERROR(XLOOKUP(A13,'Intake Responses'!$A:$A,'Intake Responses'!$V:$V),"") | O13: =IFERROR(XLOOKUP(A13,'Intake Responses'!$A:$A,'Intake Responses'!$W:$W),"") | P13: =IFERROR(XLOOKUP(A13,'Intake Responses'!$A:$A,'Intake Responses'!$X:$X),"") | Q13: =IFERROR(XLOOKUP(A13,'Intake Responses'!$A:$A,'Intake Responses'!$AF:$AF),"") | R13: =IFERROR(XLOOKUP(A13,'Intake Responses'!$A:$A,'Intake Responses'!$S:$S),"") | V13: =IFERROR(MIN(5,ROUND(((M13+O13)/2)+(IF(J13>=20,2,IF(J13>=10,1.5,IF(J13>=5,1,IF(J13>=1,0.5,0))))),1)),0) | W13: =IFERROR(SWITCH(F13,"Multiple times per day",5,"Daily",4,"Weekly",3,"Monthly",2,"Quarterly",1,"Ad hoc",1,"Unknown",0),0) | X13: =IFERROR(ROUND(AVERAGE(L13,N13),1),0) | Y13: =IFERROR(SWITCH(U13,"High",3,"Medium",2,"Low",0,"Unknown",1,1)+IF(Q13="Yes",2,IF(Q13="Unsure",1,0)),0) | Z13: =IFERROR(ROUND((V13*2)+(W13*1)+(X13*2)+(IF(T13="Easy",2,IF(T13="Medium",1,IF(T13="Hard",-1,0))))-(Y13*2),1),0) | AA13: =IFERROR(IF(S13="Not a fit","Not a Fit",IF(Y13>=5,"High Risk / Needs Review",IF(AND(Z13>=18,T13="Easy"),"Quick Win",IF(AND(Z13>=18,T13<>"Easy"),"Strategic Project",IF(Z13>=10,"Discovery Needed","Process Issue"))))),"") | AB13: =IFERROR(SWITCH(AA13,"Quick Win","Schedule prototype scoping conversation","Discovery Needed","Schedule workflow walkthrough","Strategic Project","Identify stakeholders and dependencies","High Risk / Needs Review","Review with Security/Legal/Data owner before solutioning","Process Issue","Explore process/template/documentation improvement","Not a Fit","Do not pursue at this time","Review manually"),"")
... B501: =IFERROR(XLOOKUP(A501,'Intake Responses'!$A:$A,'Intake Responses'!$E:$E),"") | C501: =IFERROR(XLOOKUP(A501,'Intake Responses'!$A:$A,'Intake Responses'!$D:$D),"") | D501: =IFERROR(XLOOKUP(A501,'Intake Responses'!$A:$A,'Intake Responses'!$F:$F),"") | F501: =IFERROR(XLOOKUP(A501,'Intake Responses'!$A:$A,'Intake Responses'!$M:$M),"") | G501: =IFERROR(XLOOKUP(A501,'Intake Responses'!$A:$A,'Intake Responses'!$N:$N),"") | H501: =IFERROR(XLOOKUP(A501,'Intake Responses'!$A:$A,'Intake Responses'!$O:$O),"") | I501: =IFERROR(SWITCH(F501,"Multiple times per day",60,"Daily",20,"Weekly",4,"Monthly",1,"Quarterly",0.33,"Ad hoc",0.5,"Unknown",0),0) | J501: =IFERROR((G501*H501*I501)/60,0) | K501: =IFERROR(J501*12,0) | L501: =IFERROR(XLOOKUP(A501,'Intake Responses'!$A:$A,'Intake Responses'!$T:$T),"") | M501: =IFERROR(XLOOKUP(A501,'Intake Responses'!$A:$A,'Intake Responses'!$U:$U),"") | N501: =IFERROR(XLOOKUP(A501,'Intake Responses'!$A:$A,'Intake Responses'!$V:$V),"") | O501: =IFERROR(XLOOKUP(A501,'Intake Responses'!$A:$A,'Intake Responses'!$W:$W),"") | P501: =IFERROR(XLOOKUP(A501,'Intake Responses'!$A:$A,'Intake Responses'!$X:$X),"") | Q501: =IFERROR(XLOOKUP(A501,'Intake Responses'!$A:$A,'Intake Responses'!$AF:$AF),"") | R501: =IFERROR(XLOOKUP(A501,'Intake Responses'!$A:$A,'Intake Responses'!$S:$S),"") | V501: =IFERROR(MIN(5,ROUND(((M501+O501)/2)+(IF(J501>=20,2,IF(J501>=10,1.5,IF(J501>=5,1,IF(J501>=1,0.5,0))))),1)),0) | W501: =IFERROR(SWITCH(F501,"Multiple times per day",5,"Daily",4,"Weekly",3,"Monthly",2,"Quarterly",1,"Ad hoc",1,"Unknown",0),0) | X501: =IFERROR(ROUND(AVERAGE(L501,N501),1),0) | Y501: =IFERROR(SWITCH(U501,"High",3,"Medium",2,"Low",0,"Unknown",1,1)+IF(Q501="Yes",2,IF(Q501="Unsure",1,0)),0) | Z501: =IFERROR(ROUND((V501*2)+(W501*1)+(X501*2)+(IF(T501="Easy",2,IF(T501="Medium",1,IF(T501="Hard",-1,0))))-(Y501*2),1),0) | AA501: =IFERROR(IF(S501="Not a fit","Not a Fit",IF(Y501>=5,"High Risk / Needs Review",IF(AND(Z501>=18,T501="Easy"),"Quick Win",IF(AND(Z501>=18,T501<>"Easy"),"Strategic Project",IF(Z501>=10,"Discovery Needed","Process Issue"))))),"") | AB501: =IFERROR(SWITCH(AA501,"Quick Win","Schedule prototype scoping conversation","Discovery Needed","Schedule workflow walkthrough","Strategic Project","Identify stakeholders and dependencies","High Risk / Needs Review","Review with Security/Legal/Data owner before solutioning","Process Issue","Explore process/template/documentation improvement","Not a Fit","Do not pursue at this time","Review manually"),"")

Sheet Discovery Sessions
A1: Discovery Session ID | B1: Opportunity ID | C1: Workflow / Task Name | D1: Session Date | E1: Facilitator | F1: Workflow Owner / SME | G1: Session Type | H1: Session Goal | I1: Summary of What We Learned | J1: Key Pain Points | K1: Risks / Guardrails | L1: Dependencies / Access Needed | M1: Likely Solution Direction | N1: Recommended Next Step | O1: Owner of Next Step | P1: Next Review Date | Q1: Link to Detailed Step Log | R1: Notes
A2: =IF(B2="","","DS-"&TEXT(ROW()-1,"0000")) | C2: =IFERROR(XLOOKUP(B2,'Opportunity Scoring'!$A:$A,'Opportunity Scoring'!$B:$B),"") | F2: =IFERROR(XLOOKUP(B2,'Opportunity Scoring'!$A:$A,'Opportunity Scoring'!$D:$D),"")
A3: =IF(B3="","","DS-"&TEXT(ROW()-1,"0000")) | C3: =IFERROR(XLOOKUP(B3,'Opportunity Scoring'!$A:$A,'Opportunity Scoring'!$B:$B),"") | F3: =IFERROR(XLOOKUP(B3,'Opportunity Scoring'!$A:$A,'Opportunity Scoring'!$D:$D),"")
A4: =IF(B4="","","DS-"&TEXT(ROW()-1,"0000")) | C4: =IFERROR(XLOOKUP(B4,'Opportunity Scoring'!$A:$A,'Opportunity Scoring'!$B:$B),"") | F4: =IFERROR(XLOOKUP(B4,'Opportunity Scoring'!$A:$A,'Opportunity Scoring'!$D:$D),"")
A5: =IF(B5="","","DS-"&TEXT(ROW()-1,"0000")) | C5: =IFERROR(XLOOKUP(B5,'Opportunity Scoring'!$A:$A,'Opportunity Scoring'!$B:$B),"") | F5: =IFERROR(XLOOKUP(B5,'Opportunity Scoring'!$A:$A,'Opportunity Scoring'!$D:$D),"")
A6: =IF(B6="","","DS-"&TEXT(ROW()-1,"0000")) | C6: =IFERROR(XLOOKUP(B6,'Opportunity Scoring'!$A:$A,'Opportunity Scoring'!$B:$B),"") | F6: =IFERROR(XLOOKUP(B6,'Opportunity Scoring'!$A:$A,'Opportunity Scoring'!$D:$D),"")
A7: =IF(B7="","","DS-"&TEXT(ROW()-1,"0000")) | C7: =IFERROR(XLOOKUP(B7,'Opportunity Scoring'!$A:$A,'Opportunity Scoring'!$B:$B),"") | F7: =IFERROR(XLOOKUP(B7,'Opportunity Scoring'!$A:$A,'Opportunity Scoring'!$D:$D),"")
A8: =IF(B8="","","DS-"&TEXT(ROW()-1,"0000")) | C8: =IFERROR(XLOOKUP(B8,'Opportunity Scoring'!$A:$A,'Opportunity Scoring'!$B:$B),"") | F8: =IFERROR(XLOOKUP(B8,'Opportunity Scoring'!$A:$A,'Opportunity Scoring'!$D:$D),"")
A9: =IF(B9="","","DS-"&TEXT(ROW()-1,"0000")) | C9: =IFERROR(XLOOKUP(B9,'Opportunity Scoring'!$A:$A,'Opportunity Scoring'!$B:$B),"") | F9: =IFERROR(XLOOKUP(B9,'Opportunity Scoring'!$A:$A,'Opportunity Scoring'!$D:$D),"")
A10: =IF(B10="","","DS-"&TEXT(ROW()-1,"0000")) | C10: =IFERROR(XLOOKUP(B10,'Opportunity Scoring'!$A:$A,'Opportunity Scoring'!$B:$B),"") | F10: =IFERROR(XLOOKUP(B10,'Opportunity Scoring'!$A:$A,'Opportunity Scoring'!$D:$D),"")
A11: =IF(B11="","","DS-"&TEXT(ROW()-1,"0000")) | C11: =IFERROR(XLOOKUP(B11,'Opportunity Scoring'!$A:$A,'Opportunity Scoring'!$B:$B),"") | F11: =IFERROR(XLOOKUP(B11,'Opportunity Scoring'!$A:$A,'Opportunity Scoring'!$D:$D),"")
A12: =IF(B12="","","DS-"&TEXT(ROW()-1,"0000")) | C12: =IFERROR(XLOOKUP(B12,'Opportunity Scoring'!$A:$A,'Opportunity Scoring'!$B:$B),"") | F12: =IFERROR(XLOOKUP(B12,'Opportunity Scoring'!$A:$A,'Opportunity Scoring'!$D:$D),"")
A13: =IF(B13="","","DS-"&TEXT(ROW()-1,"0000")) | C13: =IFERROR(XLOOKUP(B13,'Opportunity Scoring'!$A:$A,'Opportunity Scoring'!$B:$B),"") | F13: =IFERROR(XLOOKUP(B13,'Opportunity Scoring'!$A:$A,'Opportunity Scoring'!$D:$D),"")
... A501: =IF(B501="","","DS-"&TEXT(ROW()-1,"0000")) | C501: =IFERROR(XLOOKUP(B501,'Opportunity Scoring'!$A:$A,'Opportunity Scoring'!$B:$B),"") | F501: =IFERROR(XLOOKUP(B501,'Opportunity Scoring'!$A:$A,'Opportunity Scoring'!$D:$D),"")

Sheet Discovery Step Log
A1: Opportunity ID | B1: Discovery Session ID | C1: Discovery Date | D1: Facilitator | E1: Workflow Owner | F1: Current Workflow Step # | G1: Current Workflow Step Description | H1: Tool / System Used | I1: Input | J1: Output | K1: Manual Action Taken | L1: Time Spent on Step | M1: Pain Point Observed | N1: Error / Risk Point | O1: Human Judgment Required? | P1: Could This Be Automated? | Q1: Could This Be AI-Assisted? | R1: Dependency / Access Needed | S1: Notes

Sheet Opportunity Briefs
A1: Opportunity Brief Generator
A2: Selected Opportunity ID: | C2: Enter an Opportunity ID from Opportunity Scoring (e.g., WF-0001)
A3: This tab generates a structured opportunity brief from the selected Opportunity ID. Use it for stakeholder review, discovery planning, or prototype scoping.
A5: OPPORTUNITY OVERVIEW
A6: Opportunity ID | B6: =$B$2
A7: Workflow / Task Name | B7: =IFERROR(XLOOKUP($B$2,'Opportunity Scoring'!$A:$A,'Opportunity Scoring'!$B:$B),"")
A8: Team / Function | B8: =IFERROR(XLOOKUP($B$2,'Opportunity Scoring'!$A:$A,'Opportunity Scoring'!$C:$C),"")
A9: Workflow Owner | B9: =IFERROR(XLOOKUP($B$2,'Opportunity Scoring'!$A:$A,'Opportunity Scoring'!$D:$D),"")
A10: Status | B10: =IFERROR(XLOOKUP($B$2,'Opportunity Scoring'!$A:$A,'Opportunity Scoring'!$E:$E),"")
A11: Purpose of the Workflow | B11: =IFERROR(XLOOKUP($B$2,'Intake Responses'!$A:$A,'Intake Responses'!$I:$I),"")
A13: FRICTION & TIME COST
A14: Current Friction Summary | B14: =IFERROR(XLOOKUP($B$2,'Intake Responses'!$A:$A,'Intake Responses'!$L:$L),"")
A15: Friction Types | B15: =IFERROR(XLOOKUP($B$2,'Intake Responses'!$A:$A,'Intake Responses'!$S:$S),"")
A16: Pain Rating (1-5) | B16: =IFERROR(XLOOKUP($B$2,'Opportunity Scoring'!$A:$A,'Opportunity Scoring'!$L:$L),"")
A17: Frequency | B17: =IFERROR(XLOOKUP($B$2,'Opportunity Scoring'!$A:$A,'Opportunity Scoring'!$F:$F),"")
A18: Minutes Per Run | B18: =IFERROR(XLOOKUP($B$2,'Opportunity Scoring'!$A:$A,'Opportunity Scoring'!$G:$G),"")
A19: People Doing This Work | B19: =IFERROR(XLOOKUP($B$2,'Opportunity Scoring'!$A:$A,'Opportunity Scoring'!$H:$H),"")
A20: Est. Monthly Hours | B20: =IFERROR(XLOOKUP($B$2,'Opportunity Scoring'!$A:$A,'Opportunity Scoring'!$J:$J),"")
A21: Annualized Hours | B21: =IFERROR(XLOOKUP($B$2,'Opportunity Scoring'!$A:$A,'Opportunity Scoring'!$K:$K),"")
A23: BUSINESS IMPACT
A24: Business Criticality (1-5) | B24: =IFERROR(XLOOKUP($B$2,'Opportunity Scoring'!$A:$A,'Opportunity Scoring'!$M:$M),"")
A25: Urgency (1-5) | B25: =IFERROR(XLOOKUP($B$2,'Opportunity Scoring'!$A:$A,'Opportunity Scoring'!$O:$O),"")
A26: What Happens If Late/Wrong/Skipped | B26: =IFERROR(XLOOKUP($B$2,'Intake Responses'!$A:$A,'Intake Responses'!$K:$K),"")
A27: Internal People Affected | B27: =IFERROR(XLOOKUP($B$2,'Opportunity Scoring'!$A:$A,'Opportunity Scoring'!$P:$P),"")
A28: Customers / Districts / Students Affected | B28: =IFERROR(XLOOKUP($B$2,'Intake Responses'!$A:$A,'Intake Responses'!$Y:$Y),"")
A30: RISK & DATA CONSIDERATIONS
A31: Sensitive Data? | B31: =IFERROR(XLOOKUP($B$2,'Opportunity Scoring'!$A:$A,'Opportunity Scoring'!$Q:$Q),"")
A32: Risk Level | B32: =IFERROR(XLOOKUP($B$2,'Opportunity Scoring'!$A:$A,'Opportunity Scoring'!$U:$U),"")
A33: Data Types Involved | B33: =IFERROR(XLOOKUP($B$2,'Intake Responses'!$A:$A,'Intake Responses'!$AG:$AG),"")
A34: Input Data Location | B34: =IFERROR(XLOOKUP($B$2,'Intake Responses'!$A:$A,'Intake Responses'!$AH:$AH),"")
A35: Output Destination | B35: =IFERROR(XLOOKUP($B$2,'Intake Responses'!$A:$A,'Intake Responses'!$AI:$AI),"")
A37: LIKELY SOLUTION DIRECTION
A38: Likely Solution Type | B38: =IFERROR(XLOOKUP($B$2,'Opportunity Scoring'!$A:$A,'Opportunity Scoring'!$S:$S),"")
A39: Feasibility | B39: =IFERROR(XLOOKUP($B$2,'Opportunity Scoring'!$A:$A,'Opportunity Scoring'!$T:$T),"")
A40: Recommended Next Step | B40: =IFERROR(XLOOKUP($B$2,'Opportunity Scoring'!$A:$A,'Opportunity Scoring'!$AB:$AB),"")
A42: HUMAN REVIEW & GUARDRAILS
A43: Should Still Require Human Review | B43: =IFERROR(XLOOKUP($B$2,'Intake Responses'!$A:$A,'Intake Responses'!$AA:$AA),"")
A44: Should Never Be Automated | B44: =IFERROR(XLOOKUP($B$2,'Intake Responses'!$A:$A,'Intake Responses'!$AB:$AB),"")
A45: What Would Make You Trust This | B45: =IFERROR(XLOOKUP($B$2,'Intake Responses'!$A:$A,'Intake Responses'!$AC:$AC),"")
A46: What Would Make This Unusable | B46: =IFERROR(XLOOKUP($B$2,'Intake Responses'!$A:$A,'Intake Responses'!$AD:$AD),"")
...

Sheet Dashboard
A1: AI Enablement Opportunity Pipeline — Dashboard
A3: Total Opportunities | D3: =COUNTA('Opportunity Scoring'!$A$2:$A$501)
A4: Quick Wins | D4: =COUNTIF('Opportunity Scoring'!$AA$2:$AA$501,"Quick Win")
A5: Discovery Needed | D5: =COUNTIF('Opportunity Scoring'!$AA$2:$AA$501,"Discovery Needed")
A6: Strategic Projects | D6: =COUNTIF('Opportunity Scoring'!$AA$2:$AA$501,"Strategic Project")
A7: High Risk / Needs Review | D7: =COUNTIF('Opportunity Scoring'!$AA$2:$AA$501,"High Risk / Needs Review")
A9: Est. Monthly Hours (All) | D9: =ROUND(SUM('Opportunity Scoring'!$J$2:$J$501),1)
A10: Est. Annual Hours (All) | D10: =ROUND(SUM('Opportunity Scoring'!$K$2:$K$501),1)
A11: Avg Priority Score | D11: =IFERROR(ROUND(AVERAGEIF('Opportunity Scoring'!$Z$2:$Z$501,">0"),1),"—")
A12: Discovery Sessions Logged | D12: =COUNTA('Discovery Sessions'!$A$2:$A$501)
A14: Portfolio Summary Tables
A16: Opportunities by Priority Category | D16: Opportunities by Risk Level
A17: Priority Category | B17: Count | D17: Risk Level | E17: Count
A18: Quick Win | B18: =COUNTIF('Opportunity Scoring'!$AA$2:$AA$501,"Quick Win") | D18: High | E18: =COUNTIF('Opportunity Scoring'!$U$2:$U$501,"High")
A19: Discovery Needed | B19: =COUNTIF('Opportunity Scoring'!$AA$2:$AA$501,"Discovery Needed") | D19: Medium | E19: =COUNTIF('Opportunity Scoring'!$U$2:$U$501,"Medium")
A20: Strategic Project | B20: =COUNTIF('Opportunity Scoring'!$AA$2:$AA$501,"Strategic Project") | D20: Low | E20: =COUNTIF('Opportunity Scoring'!$U$2:$U$501,"Low")
A21: High Risk / Needs Review | B21: =COUNTIF('Opportunity Scoring'!$AA$2:$AA$501,"High Risk / Needs Review") | D21: Unknown | E21: =COUNTIF('Opportunity Scoring'!$U$2:$U$501,"Unknown")
A22: Process Issue | B22: =COUNTIF('Opportunity Scoring'!$AA$2:$AA$501,"Process Issue")
A23: Not a Fit | B23: =COUNTIF('Opportunity Scoring'!$AA$2:$AA$501,"Not a Fit")
A25: Discovery Sessions by Type | D25: Opportunities by Solution Type
A26: Session Type | B26: Count | D26: Solution Type | E26: Count
A27: Intake Review | B27: =COUNTIF('Discovery Sessions'!$G$2:$G$501,"Intake Review") | D27: AI-assisted writing | E27: =COUNTIF('Opportunity Scoring'!$S$2:$S$501,"AI-assisted writing")
A28: Live Workflow Walkthrough | B28: =COUNTIF('Discovery Sessions'!$G$2:$G$501,"Live Workflow Walkthrough") | D28: AI-assisted summarization | E28: =COUNTIF('Opportunity Scoring'!$S$2:$S$501,"AI-assisted summarization")
A29: Stakeholder Interview | B29: =COUNTIF('Discovery Sessions'!$G$2:$G$501,"Stakeholder Interview") | D29: AI-assisted research/retrieval | E29: =COUNTIF('Opportunity Scoring'!$S$2:$S$501,"AI-assisted research/retrieval")
A30: Async Review | B30: =COUNTIF('Discovery Sessions'!$G$2:$G$501,"Async Review") | D30: Reporting automation | E30: =COUNTIF('Opportunity Scoring'!$S$2:$S$501,"Reporting automation")
A31: Prototype Scoping | B31: =COUNTIF('Discovery Sessions'!$G$2:$G$501,"Prototype Scoping") | D31: Data pipeline/integration | E31: =COUNTIF('Opportunity Scoring'!$S$2:$S$501,"Data pipeline/integration")
A32: Follow-up | B32: =COUNTIF('Discovery Sessions'!$G$2:$G$501,"Follow-up") | D32: Workflow automation | E32: =COUNTIF('Opportunity Scoring'!$S$2:$S$501,"Workflow automation")
D33: Template/process redesign | E33: =COUNTIF('Opportunity Scoring'!$S$2:$S$501,"Template/process redesign")
D34: Knowledge management improvement | E34: =COUNTIF('Opportunity Scoring'!$S$2:$S$501,"Knowledge management improvement")
D35: Human-in-the-loop review process | E35: =COUNTIF('Opportunity Scoring'!$S$2:$S$501,"Human-in-the-loop review process")
A38: This is a portfolio/program-level view. For details on any opportunity, see Opportunity Briefs or Opportunity Scoring.

Sheet Lists & Settings
A1: Team / Function | B1: Frequency | C1: Friction Type | D1: Likely Solution Type | E1: Opportunity Status | F1: Risk Level | G1: Feasibility | H1: Priority Category | J1: Setting | K1: Value
A2: Customer Support | B2: Multiple times per day | C2: Repetitive copy/paste | D2: AI-assisted writing | E2: New | F2: Low | G2: Easy | H2: Quick Win | J2: Impact Weight | K2: 2
A3: Customer Success | B3: Daily | C3: Multi-system data gathering | D3: AI-assisted summarization | E3: Needs Discovery | F3: Medium | G3: Medium | H3: Discovery Needed | J3: Frequency Weight | K3: 1
A4: Product | B4: Weekly | C4: Manual reporting | D4: AI-assisted research/retrieval | E4: Discovery Scheduled | F4: High | G4: Hard | H4: Strategic Project | J4: Pain Weight | K4: 2
A5: Engineering | B5: Monthly | C5: Writing or rewriting | D5: Reporting automation | E5: Discovery Complete | F5: Unknown | G5: Unknown | H5: High Risk / Needs Review | J5: Feasibility Weight | K5: 1
A6: Sales | B6: Quarterly | C6: Summarizing or synthesizing information | D6: Data pipeline/integration | E6: Prototype Candidate | H6: Not a Fit | J6: Risk Penalty Weight | K6: 2
A7: Marketing | B7: Ad hoc | C7: Searching for information | D7: Workflow automation | E7: In Prototype | H7: Process Issue
A8: Operations | B8: Unknown | C8: Data cleanup or normalization | D8: Template/process redesign | E8: Implemented | J8: Note: Changing these weights will affect scoring behavior across the Opportunity Scoring tab. Adjust with care.
A9: People | C9: Manual QA/checking | D9: Knowledge management improvement | E9: Parked
A10: Finance | C10: Slow handoffs | D10: Human-in-the-loop review process | E10: Not a Fit
A11: Legal | C11: Inconsistent output quality | D11: Not enough information
A12: Security | C12: Error-prone process | D12: Not a fit
A13: IT | C13: Customer-facing delay
A14: Leadership | C14: Internal decision delay
A15: Other | C15: Compliance/privacy concern
C16: Other

Sheet Instructions
A1: Instructions — AI Enablement Workflow Friction Intake System
A3: PURPOSE
A4: This workbook is used to identify, quantify, and prioritize workflow friction opportunities that may be reduced through AI, automation, process redesign, documentation improvements, reporting improvements, integrations, or other enablement work.
A6: IMPORTANT PRINCIPLE
A7: Do not ask only: 'What should AI automate?' — Ask: 'Where is work creating unnecessary friction, and what would change if that friction were reduced?' The purpose of this workbook is to understand workflow friction first. AI may or may not be the right solution.
A9: HOW TO USE THIS WORKBOOK
A10: 1. Enter or collect new opportunities in Intake Responses.
A11: 2. Review and score each opportunity in Opportunity Scoring.
A12: 3. For promising opportunities, log each discovery conversation in Discovery Sessions.
A13: 4. During live walkthroughs, use Discovery Step Log to capture the current workflow step by step.
A14: 5. Use Opportunity Briefs to generate a structured summary for stakeholders.
A15: 6. Use Dashboard to review the overall opportunity pipeline.
A17: SHEET GUIDE
A18: Sheet / Area | B18: What it collects | C18: How to use it
A19: Intake Responses | B19: Raw descriptions of workflow friction, impact, data context, desired future state, and willingness to participate. | C19: Use as the source of truth for what the submitter knows. Do not over-score if the workflow is unclear.
A20: Opportunity Scoring | B20: Triage fields and formulas translating intake into estimated hours, impact, friction, risk, priority, and next step. | C20: Review formula outputs, then manually complete Status, Solution Type, Feasibility, Risk Level, Assignee, and notes.
A21: Discovery Sessions | B21: One row per discovery conversation, walkthrough, interview, async review, or prototype scoping session. | C21: Use as the human-readable index of discovery work. Summarizes learning, next steps, owners, and dependencies.
A22: Discovery Step Log | B22: Detailed step-by-step observations from live workflow walkthroughs. Many rows per opportunity. | C22: Filter by Opportunity ID to view one workflow. One row per step so pain, risks, and automation opportunities are specific.
A23: Opportunity Briefs | B23: Stakeholder-friendly one-page summary generated from a selected Opportunity ID. | C23: Choose the ID in B2, use the brief for discovery, prototype scoping, or stakeholder review.
A24: Dashboard | B24: Leadership/program overview of the opportunity pipeline. | C24: Use for portfolio review: volume, quick wins, risk items, time estimates, discovery activity, and solution mix.
A25: Lists & Settings | B25: Reusable dropdown values and scoring weights. | C25: Only edit intentionally; changes affect validations and scoring behavior.
A27: TRIAGE CATEGORIES
A28: Quick Win — High impact, low complexity, low risk.
A29: Discovery Needed — Promising but not yet understood deeply enough.
A30: Strategic Project — High impact but requires significant coordination or integration.
A31: High Risk / Needs Review — Involves sensitive data, compliance, legal, security, or customer-facing risk.
A32: Process Issue — Better solved by documentation, process clarification, templates, or training.
A33: Not a Fit — Low impact, inappropriate risk, or not worth pursuing.
A35: SCORING INTERPRETATION
A36: Field | B36: Meaning | C36: How to interpret it
A37: Impact Score | B37: Combines criticality, urgency, and monthly hours. | C37: Directional, not absolute.
A38: Frequency Score | B38: Based on how often the workflow occurs. | C38: High-frequency annoyances can be strong opportunities even if each instance is small.
A39: Friction Score | B39: Average of pain rating and error-proneness. | C39: High friction points to standardization, QA, or automation opportunities.
A40: Risk Penalty | B40: Penalty for risk level and sensitive data. | C40: High risk means review before solutioning, not necessarily "no."
A41: Priority Score | B41: Combined weighted score after impact, frequency, friction, feasibility, and risk. | C41: Use to sort, then apply judgment.
A42: Priority Category | B42: Formula-derived triage bucket. | C42: Use as a starting point; a reviewer can override.
A44: AI ENABLEMENT GUIDANCE
A45: Consider AI when the workflow involves: drafting, rewriting, summarizing, synthesizing, searching/retrieval, classification, pattern recognition, triage, repetitive judgment support, or transformation of messy inputs into structured outputs.
A47: Treat AI carefully when the workflow involves: sensitive data, customer-facing decisions, legal, compliance, security, financial, HR, or student data, irreversible actions, high-stakes decisions, or areas where hallucination or missing context would cause harm.
A49: Also consider: process redesign, templates, better documentation, reporting automation, system integrations, workflow automation, knowledge management improvements, human-in-the-loop review, or better ownership and handoff design.
